2024-11-19 23:15:13,010 - ERROR - Internal Server Error: /Dashboard/
Traceback (most recent call last):
  File "C:\Users\danie\AppData\Local\Programs\Python\Python310\lib\site-packages\django\db\backends\utils.py", line 105, in _execute
    return self.cursor.execute(sql, params)
  File "C:\Users\danie\AppData\Local\Programs\Python\Python310\lib\site-packages\django\db\backends\mysql\base.py", line 76, in execute
    return self.cursor.execute(query, args)
  File "C:\Users\danie\AppData\Local\Programs\Python\Python310\lib\site-packages\MySQLdb\cursors.py", line 206, in execute
    res = self._query(query)
  File "C:\Users\danie\AppData\Local\Programs\Python\Python310\lib\site-packages\MySQLdb\cursors.py", line 319, in _query
    db.query(q)
  File "C:\Users\danie\AppData\Local\Programs\Python\Python310\lib\site-packages\MySQLdb\connections.py", line 254, in query
    _mysql.connection.query(self, query)
MySQLdb.OperationalError: (1054, "Unknown column 'arancel_nombre' in 'field list'")

The above exception was the direct cause of the following exception:

Traceback (most recent call last):
  File "C:\Users\danie\AppData\Local\Programs\Python\Python310\lib\site-packages\django\core\handlers\exception.py", line 55, in inner
    response = get_response(request)
  File "C:\Users\danie\AppData\Local\Programs\Python\Python310\lib\site-packages\django\core\handlers\base.py", line 197, in _get_response
    response = wrapped_callback(request, *callback_args, **callback_kwargs)
  File "C:\Users\danie\Desktop\proyecto titulo\Causa1\views.py", line 170, in dashboard
    Notificacion.objects.filter(estadoNoti=True, estadoCausa=True, fechaNotificacion__lt=tiempo_limite).delete()
  File "C:\Users\danie\AppData\Local\Programs\Python\Python310\lib\site-packages\django\db\models\query.py", line 1188, in delete
    num_deleted, num_deleted_per_model = collector.delete()
  File "C:\Users\danie\AppData\Local\Programs\Python\Python310\lib\site-packages\django\db\models\deletion.py", line 468, in delete
    count = qs._raw_delete(using=self.using)
  File "C:\Users\danie\AppData\Local\Programs\Python\Python310\lib\site-packages\django\db\models\query.py", line 1210, in _raw_delete
    cursor = query.get_compiler(using).execute_sql(CURSOR)
  File "C:\Users\danie\AppData\Local\Programs\Python\Python310\lib\site-packages\django\db\models\sql\compiler.py", line 1574, in execute_sql
    cursor.execute(sql, params)
  File "C:\Users\danie\AppData\Local\Programs\Python\Python310\lib\site-packages\django\db\backends\utils.py", line 122, in execute
    return super().execute(sql, params)
  File "C:\Users\danie\AppData\Local\Programs\Python\Python310\lib\site-packages\django\db\backends\utils.py", line 79, in execute
    return self._execute_with_wrappers(
  File "C:\Users\danie\AppData\Local\Programs\Python\Python310\lib\site-packages\django\db\backends\utils.py", line 92, in _execute_with_wrappers
    return executor(sql, params, many, context)
  File "C:\Users\danie\AppData\Local\Programs\Python\Python310\lib\site-packages\django\db\backends\utils.py", line 100, in _execute
    with self.db.wrap_database_errors:
  File "C:\Users\danie\AppData\Local\Programs\Python\Python310\lib\site-packages\django\db\utils.py", line 91, in __exit__
    raise dj_exc_value.with_traceback(traceback) from exc_value
  File "C:\Users\danie\AppData\Local\Programs\Python\Python310\lib\site-packages\django\db\backends\utils.py", line 105, in _execute
    return self.cursor.execute(sql, params)
  File "C:\Users\danie\AppData\Local\Programs\Python\Python310\lib\site-packages\django\db\backends\mysql\base.py", line 76, in execute
    return self.cursor.execute(query, args)
  File "C:\Users\danie\AppData\Local\Programs\Python\Python310\lib\site-packages\MySQLdb\cursors.py", line 206, in execute
    res = self._query(query)
  File "C:\Users\danie\AppData\Local\Programs\Python\Python310\lib\site-packages\MySQLdb\cursors.py", line 319, in _query
    db.query(q)
  File "C:\Users\danie\AppData\Local\Programs\Python\Python310\lib\site-packages\MySQLdb\connections.py", line 254, in query
    _mysql.connection.query(self, query)
django.db.utils.OperationalError: (1054, "Unknown column 'arancel_nombre' in 'field list'")
