2024-11-20 00:04:11,186 - WARNING - Not Found: /favicon.ico
2024-11-20 00:04:19,075 - ERROR - Internal Server Error: /Dashboard/
Traceback (most recent call last):
  File "C:\Users\danie\AppData\Local\Programs\Python\Python310\lib\site-packages\django\db\backends\utils.py", line 106, in _execute
    return self.cursor.execute(sql, params)
  File "C:\Users\danie\AppData\Local\Programs\Python\Python310\lib\site-packages\django\db\backends\mysql\base.py", line 76, in execute
    return self.cursor.execute(query, args)
  File "C:\Users\danie\AppData\Local\Programs\Python\Python310\lib\site-packages\MySQLdb\cursors.py", line 206, in execute
    res = self._query(query)
  File "C:\Users\danie\AppData\Local\Programs\Python\Python310\lib\site-packages\MySQLdb\cursors.py", line 319, in _query
    db.query(q)
  File "C:\Users\danie\AppData\Local\Programs\Python\Python310\lib\site-packages\MySQLdb\connections.py", line 254, in query
    _mysql.connection.query(self, query)
MySQLdb.OperationalError: (1054, "Unknown column 'arancel_nombre' in 'field list'")

The above exception was the direct cause of the following exception:

Traceback (most recent call last):
  File "C:\Users\danie\AppData\Local\Programs\Python\Python310\lib\site-packages\django\core\handlers\exception.py", line 55, in inner
    response = get_response(request)
  File "C:\Users\danie\AppData\Local\Programs\Python\Python310\lib\site-packages\django\core\handlers\base.py", line 197, in _get_response
    response = wrapped_callback(request, *callback_args, **callback_kwargs)
  File "C:\Users\danie\Desktop\proyecto titulo\Causa1\views.py", line 175, in dashboard
    Notificacion.objects.filter(estadoNoti=True, estadoCausa=True, fechaNotificacion__lt=tiempo_limite).delete()
  File "C:\Users\danie\AppData\Local\Programs\Python\Python310\lib\site-packages\django\db\models\query.py", line 1188, in delete
    num_deleted, num_deleted_per_model = collector.delete()
  File "C:\Users\danie\AppData\Local\Programs\Python\Python310\lib\site-packages\django\db\models\deletion.py", line 468, in delete
    count = qs._raw_delete(using=self.using)
  File "C:\Users\danie\AppData\Local\Programs\Python\Python310\lib\site-packages\django\db\models\query.py", line 1210, in _raw_delete
    cursor = query.get_compiler(using).execute_sql(CURSOR)
  File "C:\Users\danie\AppData\Local\Programs\Python\Python310\lib\site-packages\django\db\models\sql\compiler.py", line 1574, in execute_sql
    cursor.execute(sql, params)
  File "C:\Users\danie\AppData\Local\Programs\Python\Python310\lib\site-packages\django\db\backends\utils.py", line 123, in execute
    return super().execute(sql, params)
  File "C:\Users\danie\AppData\Local\Programs\Python\Python310\lib\site-packages\django\db\backends\utils.py", line 80, in execute
    return self._execute_with_wrappers(
  File "C:\Users\danie\AppData\Local\Programs\Python\Python310\lib\site-packages\django\db\backends\utils.py", line 93, in _execute_with_wrappers
    return executor(sql, params, many, context)
  File "C:\Users\danie\AppData\Local\Programs\Python\Python310\lib\site-packages\django\db\backends\utils.py", line 101, in _execute
    with self.db.wrap_database_errors:
  File "C:\Users\danie\AppData\Local\Programs\Python\Python310\lib\site-packages\django\db\utils.py", line 91, in __exit__
    raise dj_exc_value.with_traceback(traceback) from exc_value
  File "C:\Users\danie\AppData\Local\Programs\Python\Python310\lib\site-packages\django\db\backends\utils.py", line 106, in _execute
    return self.cursor.execute(sql, params)
  File "C:\Users\danie\AppData\Local\Programs\Python\Python310\lib\site-packages\django\db\backends\mysql\base.py", line 76, in execute
    return self.cursor.execute(query, args)
  File "C:\Users\danie\AppData\Local\Programs\Python\Python310\lib\site-packages\MySQLdb\cursors.py", line 206, in execute
    res = self._query(query)
  File "C:\Users\danie\AppData\Local\Programs\Python\Python310\lib\site-packages\MySQLdb\cursors.py", line 319, in _query
    db.query(q)
  File "C:\Users\danie\AppData\Local\Programs\Python\Python310\lib\site-packages\MySQLdb\connections.py", line 254, in query
    _mysql.connection.query(self, query)
django.db.utils.OperationalError: (1054, "Unknown column 'arancel_nombre' in 'field list'")
2024-11-20 00:05:10,910 - INFO - C:\Users\danie\AppData\Local\Programs\Python\Python310\Lib\site-packages\django\db\backends\utils.py changed, reloading.
2024-11-20 00:05:27,465 - INFO - C:\Users\danie\AppData\Local\Programs\Python\Python310\Lib\site-packages\django\db\backends\utils.py changed, reloading.
2024-11-20 00:06:12,368 - ERROR - Internal Server Error: /Dashboard/
Traceback (most recent call last):
  File "C:\Users\danie\AppData\Local\Programs\Python\Python310\lib\site-packages\django\db\backends\utils.py", line 106, in _execute
    return self.cursor.execute(sql, params)
  File "C:\Users\danie\AppData\Local\Programs\Python\Python310\lib\site-packages\django\db\backends\mysql\base.py", line 76, in execute
    return self.cursor.execute(query, args)
  File "C:\Users\danie\AppData\Local\Programs\Python\Python310\lib\site-packages\MySQLdb\cursors.py", line 206, in execute
    res = self._query(query)
  File "C:\Users\danie\AppData\Local\Programs\Python\Python310\lib\site-packages\MySQLdb\cursors.py", line 319, in _query
    db.query(q)
  File "C:\Users\danie\AppData\Local\Programs\Python\Python310\lib\site-packages\MySQLdb\connections.py", line 254, in query
    _mysql.connection.query(self, query)
MySQLdb.OperationalError: (1054, "Unknown column 'arancel_nombre' in 'field list'")

The above exception was the direct cause of the following exception:

Traceback (most recent call last):
  File "C:\Users\danie\AppData\Local\Programs\Python\Python310\lib\site-packages\django\core\handlers\exception.py", line 55, in inner
    response = get_response(request)
  File "C:\Users\danie\AppData\Local\Programs\Python\Python310\lib\site-packages\django\core\handlers\base.py", line 197, in _get_response
    response = wrapped_callback(request, *callback_args, **callback_kwargs)
  File "C:\Users\danie\Desktop\proyecto titulo\Causa1\views.py", line 175, in dashboard
    Notificacion.objects.filter(estadoNoti=True, estadoCausa=True, fechaNotificacion__lt=tiempo_limite).delete()
  File "C:\Users\danie\AppData\Local\Programs\Python\Python310\lib\site-packages\django\db\models\query.py", line 1188, in delete
    num_deleted, num_deleted_per_model = collector.delete()
  File "C:\Users\danie\AppData\Local\Programs\Python\Python310\lib\site-packages\django\db\models\deletion.py", line 468, in delete
    count = qs._raw_delete(using=self.using)
  File "C:\Users\danie\AppData\Local\Programs\Python\Python310\lib\site-packages\django\db\models\query.py", line 1210, in _raw_delete
    cursor = query.get_compiler(using).execute_sql(CURSOR)
  File "C:\Users\danie\AppData\Local\Programs\Python\Python310\lib\site-packages\django\db\models\sql\compiler.py", line 1574, in execute_sql
    cursor.execute(sql, params)
  File "C:\Users\danie\AppData\Local\Programs\Python\Python310\lib\site-packages\django\db\backends\utils.py", line 123, in execute
    return super().execute(sql, params)
  File "C:\Users\danie\AppData\Local\Programs\Python\Python310\lib\site-packages\django\db\backends\utils.py", line 80, in execute
    return self._execute_with_wrappers(
  File "C:\Users\danie\AppData\Local\Programs\Python\Python310\lib\site-packages\django\db\backends\utils.py", line 93, in _execute_with_wrappers
    return executor(sql, params, many, context)
  File "C:\Users\danie\AppData\Local\Programs\Python\Python310\lib\site-packages\django\db\backends\utils.py", line 101, in _execute
    with self.db.wrap_database_errors:
  File "C:\Users\danie\AppData\Local\Programs\Python\Python310\lib\site-packages\django\db\utils.py", line 91, in __exit__
    raise dj_exc_value.with_traceback(traceback) from exc_value
  File "C:\Users\danie\AppData\Local\Programs\Python\Python310\lib\site-packages\django\db\backends\utils.py", line 106, in _execute
    return self.cursor.execute(sql, params)
  File "C:\Users\danie\AppData\Local\Programs\Python\Python310\lib\site-packages\django\db\backends\mysql\base.py", line 76, in execute
    return self.cursor.execute(query, args)
  File "C:\Users\danie\AppData\Local\Programs\Python\Python310\lib\site-packages\MySQLdb\cursors.py", line 206, in execute
    res = self._query(query)
  File "C:\Users\danie\AppData\Local\Programs\Python\Python310\lib\site-packages\MySQLdb\cursors.py", line 319, in _query
    db.query(q)
  File "C:\Users\danie\AppData\Local\Programs\Python\Python310\lib\site-packages\MySQLdb\connections.py", line 254, in query
    _mysql.connection.query(self, query)
django.db.utils.OperationalError: (1054, "Unknown column 'arancel_nombre' in 'field list'")
2024-11-20 00:08:10,219 - WARNING - Not Found: /favicon.ico
2024-11-20 00:08:17,843 - ERROR - Internal Server Error: /Dashboard/
Traceback (most recent call last):
  File "C:\Users\danie\AppData\Local\Programs\Python\Python310\lib\site-packages\django\db\backends\utils.py", line 106, in _execute
    return self.cursor.execute(sql, params)
  File "C:\Users\danie\AppData\Local\Programs\Python\Python310\lib\site-packages\django\db\backends\mysql\base.py", line 76, in execute
    return self.cursor.execute(query, args)
  File "C:\Users\danie\AppData\Local\Programs\Python\Python310\lib\site-packages\MySQLdb\cursors.py", line 206, in execute
    res = self._query(query)
  File "C:\Users\danie\AppData\Local\Programs\Python\Python310\lib\site-packages\MySQLdb\cursors.py", line 319, in _query
    db.query(q)
  File "C:\Users\danie\AppData\Local\Programs\Python\Python310\lib\site-packages\MySQLdb\connections.py", line 254, in query
    _mysql.connection.query(self, query)
MySQLdb.OperationalError: (1054, "Unknown column 'arancel_nombre' in 'field list'")

The above exception was the direct cause of the following exception:

Traceback (most recent call last):
  File "C:\Users\danie\AppData\Local\Programs\Python\Python310\lib\site-packages\django\core\handlers\exception.py", line 55, in inner
    response = get_response(request)
  File "C:\Users\danie\AppData\Local\Programs\Python\Python310\lib\site-packages\django\core\handlers\base.py", line 197, in _get_response
    response = wrapped_callback(request, *callback_args, **callback_kwargs)
  File "C:\Users\danie\Desktop\proyecto titulo\Causa1\views.py", line 175, in dashboard
    Notificacion.objects.filter(estadoNoti=True, estadoCausa=True, fechaNotificacion__lt=tiempo_limite).delete()
  File "C:\Users\danie\AppData\Local\Programs\Python\Python310\lib\site-packages\django\db\models\query.py", line 1188, in delete
    num_deleted, num_deleted_per_model = collector.delete()
  File "C:\Users\danie\AppData\Local\Programs\Python\Python310\lib\site-packages\django\db\models\deletion.py", line 468, in delete
    count = qs._raw_delete(using=self.using)
  File "C:\Users\danie\AppData\Local\Programs\Python\Python310\lib\site-packages\django\db\models\query.py", line 1210, in _raw_delete
    cursor = query.get_compiler(using).execute_sql(CURSOR)
  File "C:\Users\danie\AppData\Local\Programs\Python\Python310\lib\site-packages\django\db\models\sql\compiler.py", line 1574, in execute_sql
    cursor.execute(sql, params)
  File "C:\Users\danie\AppData\Local\Programs\Python\Python310\lib\site-packages\django\db\backends\utils.py", line 123, in execute
    return super().execute(sql, params)
  File "C:\Users\danie\AppData\Local\Programs\Python\Python310\lib\site-packages\django\db\backends\utils.py", line 80, in execute
    return self._execute_with_wrappers(
  File "C:\Users\danie\AppData\Local\Programs\Python\Python310\lib\site-packages\django\db\backends\utils.py", line 93, in _execute_with_wrappers
    return executor(sql, params, many, context)
  File "C:\Users\danie\AppData\Local\Programs\Python\Python310\lib\site-packages\django\db\backends\utils.py", line 101, in _execute
    with self.db.wrap_database_errors:
  File "C:\Users\danie\AppData\Local\Programs\Python\Python310\lib\site-packages\django\db\utils.py", line 91, in __exit__
    raise dj_exc_value.with_traceback(traceback) from exc_value
  File "C:\Users\danie\AppData\Local\Programs\Python\Python310\lib\site-packages\django\db\backends\utils.py", line 106, in _execute
    return self.cursor.execute(sql, params)
  File "C:\Users\danie\AppData\Local\Programs\Python\Python310\lib\site-packages\django\db\backends\mysql\base.py", line 76, in execute
    return self.cursor.execute(query, args)
  File "C:\Users\danie\AppData\Local\Programs\Python\Python310\lib\site-packages\MySQLdb\cursors.py", line 206, in execute
    res = self._query(query)
  File "C:\Users\danie\AppData\Local\Programs\Python\Python310\lib\site-packages\MySQLdb\cursors.py", line 319, in _query
    db.query(q)
  File "C:\Users\danie\AppData\Local\Programs\Python\Python310\lib\site-packages\MySQLdb\connections.py", line 254, in query
    _mysql.connection.query(self, query)
django.db.utils.OperationalError: (1054, "Unknown column 'arancel_nombre' in 'field list'")
2024-11-20 00:11:28,701 - INFO - C:\Users\danie\Desktop\proyecto titulo\Causa1\views.py changed, reloading.
2024-11-20 00:11:42,638 - ERROR - Internal Server Error: /Dashboard/
Traceback (most recent call last):
  File "C:\Users\danie\AppData\Local\Programs\Python\Python310\lib\site-packages\django\db\backends\utils.py", line 106, in _execute
    return self.cursor.execute(sql, params)
  File "C:\Users\danie\AppData\Local\Programs\Python\Python310\lib\site-packages\django\db\backends\mysql\base.py", line 76, in execute
    return self.cursor.execute(query, args)
  File "C:\Users\danie\AppData\Local\Programs\Python\Python310\lib\site-packages\MySQLdb\cursors.py", line 206, in execute
    res = self._query(query)
  File "C:\Users\danie\AppData\Local\Programs\Python\Python310\lib\site-packages\MySQLdb\cursors.py", line 319, in _query
    db.query(q)
  File "C:\Users\danie\AppData\Local\Programs\Python\Python310\lib\site-packages\MySQLdb\connections.py", line 254, in query
    _mysql.connection.query(self, query)
MySQLdb.OperationalError: (1054, "Unknown column 'arancel_nombre' in 'field list'")

The above exception was the direct cause of the following exception:

Traceback (most recent call last):
  File "C:\Users\danie\AppData\Local\Programs\Python\Python310\lib\site-packages\django\core\handlers\exception.py", line 55, in inner
    response = get_response(request)
  File "C:\Users\danie\AppData\Local\Programs\Python\Python310\lib\site-packages\django\core\handlers\base.py", line 197, in _get_response
    response = wrapped_callback(request, *callback_args, **callback_kwargs)
  File "C:\Users\danie\Desktop\proyecto titulo\Causa1\views.py", line 175, in dashboard
    Notificacion.objects.filter(estadoNoti=True, estadoCausa=True, fechaNotificacion__lt=tiempo_limite).delete()
  File "C:\Users\danie\AppData\Local\Programs\Python\Python310\lib\site-packages\django\db\models\query.py", line 1188, in delete
    num_deleted, num_deleted_per_model = collector.delete()
  File "C:\Users\danie\AppData\Local\Programs\Python\Python310\lib\site-packages\django\db\models\deletion.py", line 468, in delete
    count = qs._raw_delete(using=self.using)
  File "C:\Users\danie\AppData\Local\Programs\Python\Python310\lib\site-packages\django\db\models\query.py", line 1210, in _raw_delete
    cursor = query.get_compiler(using).execute_sql(CURSOR)
  File "C:\Users\danie\AppData\Local\Programs\Python\Python310\lib\site-packages\django\db\models\sql\compiler.py", line 1574, in execute_sql
    cursor.execute(sql, params)
  File "C:\Users\danie\AppData\Local\Programs\Python\Python310\lib\site-packages\django\db\backends\utils.py", line 123, in execute
    return super().execute(sql, params)
  File "C:\Users\danie\AppData\Local\Programs\Python\Python310\lib\site-packages\django\db\backends\utils.py", line 80, in execute
    return self._execute_with_wrappers(
  File "C:\Users\danie\AppData\Local\Programs\Python\Python310\lib\site-packages\django\db\backends\utils.py", line 93, in _execute_with_wrappers
    return executor(sql, params, many, context)
  File "C:\Users\danie\AppData\Local\Programs\Python\Python310\lib\site-packages\django\db\backends\utils.py", line 101, in _execute
    with self.db.wrap_database_errors:
  File "C:\Users\danie\AppData\Local\Programs\Python\Python310\lib\site-packages\django\db\utils.py", line 91, in __exit__
    raise dj_exc_value.with_traceback(traceback) from exc_value
  File "C:\Users\danie\AppData\Local\Programs\Python\Python310\lib\site-packages\django\db\backends\utils.py", line 106, in _execute
    return self.cursor.execute(sql, params)
  File "C:\Users\danie\AppData\Local\Programs\Python\Python310\lib\site-packages\django\db\backends\mysql\base.py", line 76, in execute
    return self.cursor.execute(query, args)
  File "C:\Users\danie\AppData\Local\Programs\Python\Python310\lib\site-packages\MySQLdb\cursors.py", line 206, in execute
    res = self._query(query)
  File "C:\Users\danie\AppData\Local\Programs\Python\Python310\lib\site-packages\MySQLdb\cursors.py", line 319, in _query
    db.query(q)
  File "C:\Users\danie\AppData\Local\Programs\Python\Python310\lib\site-packages\MySQLdb\connections.py", line 254, in query
    _mysql.connection.query(self, query)
django.db.utils.OperationalError: (1054, "Unknown column 'arancel_nombre' in 'field list'")
2024-11-20 00:19:50,958 - WARNING - Not Found: /favicon.ico
2024-11-20 00:19:58,481 - ERROR - Internal Server Error: /Dashboard/
Traceback (most recent call last):
  File "C:\Users\danie\AppData\Local\Programs\Python\Python310\lib\site-packages\django\db\backends\utils.py", line 106, in _execute
    return self.cursor.execute(sql, params)
  File "C:\Users\danie\AppData\Local\Programs\Python\Python310\lib\site-packages\django\db\backends\mysql\base.py", line 76, in execute
    return self.cursor.execute(query, args)
  File "C:\Users\danie\AppData\Local\Programs\Python\Python310\lib\site-packages\MySQLdb\cursors.py", line 206, in execute
    res = self._query(query)
  File "C:\Users\danie\AppData\Local\Programs\Python\Python310\lib\site-packages\MySQLdb\cursors.py", line 319, in _query
    db.query(q)
  File "C:\Users\danie\AppData\Local\Programs\Python\Python310\lib\site-packages\MySQLdb\connections.py", line 254, in query
    _mysql.connection.query(self, query)
MySQLdb.OperationalError: (1054, "Unknown column 'arancel_nombre' in 'field list'")

The above exception was the direct cause of the following exception:

Traceback (most recent call last):
  File "C:\Users\danie\AppData\Local\Programs\Python\Python310\lib\site-packages\django\core\handlers\exception.py", line 55, in inner
    response = get_response(request)
  File "C:\Users\danie\AppData\Local\Programs\Python\Python310\lib\site-packages\django\core\handlers\base.py", line 197, in _get_response
    response = wrapped_callback(request, *callback_args, **callback_kwargs)
  File "C:\Users\danie\Desktop\proyecto titulo\Causa1\views.py", line 175, in dashboard
    Notificacion.objects.filter(estadoNoti=True, estadoCausa=True, fechaNotificacion__lt=tiempo_limite).delete()
  File "C:\Users\danie\AppData\Local\Programs\Python\Python310\lib\site-packages\django\db\models\query.py", line 1188, in delete
    num_deleted, num_deleted_per_model = collector.delete()
  File "C:\Users\danie\AppData\Local\Programs\Python\Python310\lib\site-packages\django\db\models\deletion.py", line 468, in delete
    count = qs._raw_delete(using=self.using)
  File "C:\Users\danie\AppData\Local\Programs\Python\Python310\lib\site-packages\django\db\models\query.py", line 1210, in _raw_delete
    cursor = query.get_compiler(using).execute_sql(CURSOR)
  File "C:\Users\danie\AppData\Local\Programs\Python\Python310\lib\site-packages\django\db\models\sql\compiler.py", line 1574, in execute_sql
    cursor.execute(sql, params)
  File "C:\Users\danie\AppData\Local\Programs\Python\Python310\lib\site-packages\django\db\backends\utils.py", line 123, in execute
    return super().execute(sql, params)
  File "C:\Users\danie\AppData\Local\Programs\Python\Python310\lib\site-packages\django\db\backends\utils.py", line 80, in execute
    return self._execute_with_wrappers(
  File "C:\Users\danie\AppData\Local\Programs\Python\Python310\lib\site-packages\django\db\backends\utils.py", line 93, in _execute_with_wrappers
    return executor(sql, params, many, context)
  File "C:\Users\danie\AppData\Local\Programs\Python\Python310\lib\site-packages\django\db\backends\utils.py", line 101, in _execute
    with self.db.wrap_database_errors:
  File "C:\Users\danie\AppData\Local\Programs\Python\Python310\lib\site-packages\django\db\utils.py", line 91, in __exit__
    raise dj_exc_value.with_traceback(traceback) from exc_value
  File "C:\Users\danie\AppData\Local\Programs\Python\Python310\lib\site-packages\django\db\backends\utils.py", line 106, in _execute
    return self.cursor.execute(sql, params)
  File "C:\Users\danie\AppData\Local\Programs\Python\Python310\lib\site-packages\django\db\backends\mysql\base.py", line 76, in execute
    return self.cursor.execute(query, args)
  File "C:\Users\danie\AppData\Local\Programs\Python\Python310\lib\site-packages\MySQLdb\cursors.py", line 206, in execute
    res = self._query(query)
  File "C:\Users\danie\AppData\Local\Programs\Python\Python310\lib\site-packages\MySQLdb\cursors.py", line 319, in _query
    db.query(q)
  File "C:\Users\danie\AppData\Local\Programs\Python\Python310\lib\site-packages\MySQLdb\connections.py", line 254, in query
    _mysql.connection.query(self, query)
django.db.utils.OperationalError: (1054, "Unknown column 'arancel_nombre' in 'field list'")
2024-11-20 00:20:27,464 - ERROR - Internal Server Error: /Dashboard/
Traceback (most recent call last):
  File "C:\Users\danie\AppData\Local\Programs\Python\Python310\lib\site-packages\django\db\backends\utils.py", line 106, in _execute
    return self.cursor.execute(sql, params)
  File "C:\Users\danie\AppData\Local\Programs\Python\Python310\lib\site-packages\django\db\backends\mysql\base.py", line 76, in execute
    return self.cursor.execute(query, args)
  File "C:\Users\danie\AppData\Local\Programs\Python\Python310\lib\site-packages\MySQLdb\cursors.py", line 206, in execute
    res = self._query(query)
  File "C:\Users\danie\AppData\Local\Programs\Python\Python310\lib\site-packages\MySQLdb\cursors.py", line 319, in _query
    db.query(q)
  File "C:\Users\danie\AppData\Local\Programs\Python\Python310\lib\site-packages\MySQLdb\connections.py", line 254, in query
    _mysql.connection.query(self, query)
MySQLdb.OperationalError: (1054, "Unknown column 'arancel_nombre' in 'field list'")

The above exception was the direct cause of the following exception:

Traceback (most recent call last):
  File "C:\Users\danie\AppData\Local\Programs\Python\Python310\lib\site-packages\django\core\handlers\exception.py", line 55, in inner
    response = get_response(request)
  File "C:\Users\danie\AppData\Local\Programs\Python\Python310\lib\site-packages\django\core\handlers\base.py", line 197, in _get_response
    response = wrapped_callback(request, *callback_args, **callback_kwargs)
  File "C:\Users\danie\Desktop\proyecto titulo\Causa1\views.py", line 175, in dashboard
    Notificacion.objects.filter(estadoNoti=True, estadoCausa=True, fechaNotificacion__lt=tiempo_limite).delete()
  File "C:\Users\danie\AppData\Local\Programs\Python\Python310\lib\site-packages\django\db\models\query.py", line 1188, in delete
    num_deleted, num_deleted_per_model = collector.delete()
  File "C:\Users\danie\AppData\Local\Programs\Python\Python310\lib\site-packages\django\db\models\deletion.py", line 468, in delete
    count = qs._raw_delete(using=self.using)
  File "C:\Users\danie\AppData\Local\Programs\Python\Python310\lib\site-packages\django\db\models\query.py", line 1210, in _raw_delete
    cursor = query.get_compiler(using).execute_sql(CURSOR)
  File "C:\Users\danie\AppData\Local\Programs\Python\Python310\lib\site-packages\django\db\models\sql\compiler.py", line 1574, in execute_sql
    cursor.execute(sql, params)
  File "C:\Users\danie\AppData\Local\Programs\Python\Python310\lib\site-packages\django\db\backends\utils.py", line 123, in execute
    return super().execute(sql, params)
  File "C:\Users\danie\AppData\Local\Programs\Python\Python310\lib\site-packages\django\db\backends\utils.py", line 80, in execute
    return self._execute_with_wrappers(
  File "C:\Users\danie\AppData\Local\Programs\Python\Python310\lib\site-packages\django\db\backends\utils.py", line 93, in _execute_with_wrappers
    return executor(sql, params, many, context)
  File "C:\Users\danie\AppData\Local\Programs\Python\Python310\lib\site-packages\django\db\backends\utils.py", line 101, in _execute
    with self.db.wrap_database_errors:
  File "C:\Users\danie\AppData\Local\Programs\Python\Python310\lib\site-packages\django\db\utils.py", line 91, in __exit__
    raise dj_exc_value.with_traceback(traceback) from exc_value
  File "C:\Users\danie\AppData\Local\Programs\Python\Python310\lib\site-packages\django\db\backends\utils.py", line 106, in _execute
    return self.cursor.execute(sql, params)
  File "C:\Users\danie\AppData\Local\Programs\Python\Python310\lib\site-packages\django\db\backends\mysql\base.py", line 76, in execute
    return self.cursor.execute(query, args)
  File "C:\Users\danie\AppData\Local\Programs\Python\Python310\lib\site-packages\MySQLdb\cursors.py", line 206, in execute
    res = self._query(query)
  File "C:\Users\danie\AppData\Local\Programs\Python\Python310\lib\site-packages\MySQLdb\cursors.py", line 319, in _query
    db.query(q)
  File "C:\Users\danie\AppData\Local\Programs\Python\Python310\lib\site-packages\MySQLdb\connections.py", line 254, in query
    _mysql.connection.query(self, query)
django.db.utils.OperationalError: (1054, "Unknown column 'arancel_nombre' in 'field list'")
2024-11-20 00:20:33,229 - ERROR - Internal Server Error: /Dashboard/
Traceback (most recent call last):
  File "C:\Users\danie\AppData\Local\Programs\Python\Python310\lib\site-packages\django\db\backends\utils.py", line 106, in _execute
    return self.cursor.execute(sql, params)
  File "C:\Users\danie\AppData\Local\Programs\Python\Python310\lib\site-packages\django\db\backends\mysql\base.py", line 76, in execute
    return self.cursor.execute(query, args)
  File "C:\Users\danie\AppData\Local\Programs\Python\Python310\lib\site-packages\MySQLdb\cursors.py", line 206, in execute
    res = self._query(query)
  File "C:\Users\danie\AppData\Local\Programs\Python\Python310\lib\site-packages\MySQLdb\cursors.py", line 319, in _query
    db.query(q)
  File "C:\Users\danie\AppData\Local\Programs\Python\Python310\lib\site-packages\MySQLdb\connections.py", line 254, in query
    _mysql.connection.query(self, query)
MySQLdb.OperationalError: (1054, "Unknown column 'arancel_nombre' in 'field list'")

The above exception was the direct cause of the following exception:

Traceback (most recent call last):
  File "C:\Users\danie\AppData\Local\Programs\Python\Python310\lib\site-packages\django\core\handlers\exception.py", line 55, in inner
    response = get_response(request)
  File "C:\Users\danie\AppData\Local\Programs\Python\Python310\lib\site-packages\django\core\handlers\base.py", line 197, in _get_response
    response = wrapped_callback(request, *callback_args, **callback_kwargs)
  File "C:\Users\danie\Desktop\proyecto titulo\Causa1\views.py", line 175, in dashboard
    Notificacion.objects.filter(estadoNoti=True, estadoCausa=True, fechaNotificacion__lt=tiempo_limite).delete()
  File "C:\Users\danie\AppData\Local\Programs\Python\Python310\lib\site-packages\django\db\models\query.py", line 1188, in delete
    num_deleted, num_deleted_per_model = collector.delete()
  File "C:\Users\danie\AppData\Local\Programs\Python\Python310\lib\site-packages\django\db\models\deletion.py", line 468, in delete
    count = qs._raw_delete(using=self.using)
  File "C:\Users\danie\AppData\Local\Programs\Python\Python310\lib\site-packages\django\db\models\query.py", line 1210, in _raw_delete
    cursor = query.get_compiler(using).execute_sql(CURSOR)
  File "C:\Users\danie\AppData\Local\Programs\Python\Python310\lib\site-packages\django\db\models\sql\compiler.py", line 1574, in execute_sql
    cursor.execute(sql, params)
  File "C:\Users\danie\AppData\Local\Programs\Python\Python310\lib\site-packages\django\db\backends\utils.py", line 123, in execute
    return super().execute(sql, params)
  File "C:\Users\danie\AppData\Local\Programs\Python\Python310\lib\site-packages\django\db\backends\utils.py", line 80, in execute
    return self._execute_with_wrappers(
  File "C:\Users\danie\AppData\Local\Programs\Python\Python310\lib\site-packages\django\db\backends\utils.py", line 93, in _execute_with_wrappers
    return executor(sql, params, many, context)
  File "C:\Users\danie\AppData\Local\Programs\Python\Python310\lib\site-packages\django\db\backends\utils.py", line 101, in _execute
    with self.db.wrap_database_errors:
  File "C:\Users\danie\AppData\Local\Programs\Python\Python310\lib\site-packages\django\db\utils.py", line 91, in __exit__
    raise dj_exc_value.with_traceback(traceback) from exc_value
  File "C:\Users\danie\AppData\Local\Programs\Python\Python310\lib\site-packages\django\db\backends\utils.py", line 106, in _execute
    return self.cursor.execute(sql, params)
  File "C:\Users\danie\AppData\Local\Programs\Python\Python310\lib\site-packages\django\db\backends\mysql\base.py", line 76, in execute
    return self.cursor.execute(query, args)
  File "C:\Users\danie\AppData\Local\Programs\Python\Python310\lib\site-packages\MySQLdb\cursors.py", line 206, in execute
    res = self._query(query)
  File "C:\Users\danie\AppData\Local\Programs\Python\Python310\lib\site-packages\MySQLdb\cursors.py", line 319, in _query
    db.query(q)
  File "C:\Users\danie\AppData\Local\Programs\Python\Python310\lib\site-packages\MySQLdb\connections.py", line 254, in query
    _mysql.connection.query(self, query)
django.db.utils.OperationalError: (1054, "Unknown column 'arancel_nombre' in 'field list'")
2024-11-20 00:20:43,905 - ERROR - Internal Server Error: /Dashboard/
Traceback (most recent call last):
  File "C:\Users\danie\AppData\Local\Programs\Python\Python310\lib\site-packages\django\db\backends\utils.py", line 106, in _execute
    return self.cursor.execute(sql, params)
  File "C:\Users\danie\AppData\Local\Programs\Python\Python310\lib\site-packages\django\db\backends\mysql\base.py", line 76, in execute
    return self.cursor.execute(query, args)
  File "C:\Users\danie\AppData\Local\Programs\Python\Python310\lib\site-packages\MySQLdb\cursors.py", line 206, in execute
    res = self._query(query)
  File "C:\Users\danie\AppData\Local\Programs\Python\Python310\lib\site-packages\MySQLdb\cursors.py", line 319, in _query
    db.query(q)
  File "C:\Users\danie\AppData\Local\Programs\Python\Python310\lib\site-packages\MySQLdb\connections.py", line 254, in query
    _mysql.connection.query(self, query)
MySQLdb.OperationalError: (1054, "Unknown column 'arancel_nombre' in 'field list'")

The above exception was the direct cause of the following exception:

Traceback (most recent call last):
  File "C:\Users\danie\AppData\Local\Programs\Python\Python310\lib\site-packages\django\core\handlers\exception.py", line 55, in inner
    response = get_response(request)
  File "C:\Users\danie\AppData\Local\Programs\Python\Python310\lib\site-packages\django\core\handlers\base.py", line 197, in _get_response
    response = wrapped_callback(request, *callback_args, **callback_kwargs)
  File "C:\Users\danie\Desktop\proyecto titulo\Causa1\views.py", line 175, in dashboard
    Notificacion.objects.filter(estadoNoti=True, estadoCausa=True, fechaNotificacion__lt=tiempo_limite).delete()
  File "C:\Users\danie\AppData\Local\Programs\Python\Python310\lib\site-packages\django\db\models\query.py", line 1188, in delete
    num_deleted, num_deleted_per_model = collector.delete()
  File "C:\Users\danie\AppData\Local\Programs\Python\Python310\lib\site-packages\django\db\models\deletion.py", line 468, in delete
    count = qs._raw_delete(using=self.using)
  File "C:\Users\danie\AppData\Local\Programs\Python\Python310\lib\site-packages\django\db\models\query.py", line 1210, in _raw_delete
    cursor = query.get_compiler(using).execute_sql(CURSOR)
  File "C:\Users\danie\AppData\Local\Programs\Python\Python310\lib\site-packages\django\db\models\sql\compiler.py", line 1574, in execute_sql
    cursor.execute(sql, params)
  File "C:\Users\danie\AppData\Local\Programs\Python\Python310\lib\site-packages\django\db\backends\utils.py", line 123, in execute
    return super().execute(sql, params)
  File "C:\Users\danie\AppData\Local\Programs\Python\Python310\lib\site-packages\django\db\backends\utils.py", line 80, in execute
    return self._execute_with_wrappers(
  File "C:\Users\danie\AppData\Local\Programs\Python\Python310\lib\site-packages\django\db\backends\utils.py", line 93, in _execute_with_wrappers
    return executor(sql, params, many, context)
  File "C:\Users\danie\AppData\Local\Programs\Python\Python310\lib\site-packages\django\db\backends\utils.py", line 101, in _execute
    with self.db.wrap_database_errors:
  File "C:\Users\danie\AppData\Local\Programs\Python\Python310\lib\site-packages\django\db\utils.py", line 91, in __exit__
    raise dj_exc_value.with_traceback(traceback) from exc_value
  File "C:\Users\danie\AppData\Local\Programs\Python\Python310\lib\site-packages\django\db\backends\utils.py", line 106, in _execute
    return self.cursor.execute(sql, params)
  File "C:\Users\danie\AppData\Local\Programs\Python\Python310\lib\site-packages\django\db\backends\mysql\base.py", line 76, in execute
    return self.cursor.execute(query, args)
  File "C:\Users\danie\AppData\Local\Programs\Python\Python310\lib\site-packages\MySQLdb\cursors.py", line 206, in execute
    res = self._query(query)
  File "C:\Users\danie\AppData\Local\Programs\Python\Python310\lib\site-packages\MySQLdb\cursors.py", line 319, in _query
    db.query(q)
  File "C:\Users\danie\AppData\Local\Programs\Python\Python310\lib\site-packages\MySQLdb\connections.py", line 254, in query
    _mysql.connection.query(self, query)
django.db.utils.OperationalError: (1054, "Unknown column 'arancel_nombre' in 'field list'")
2024-11-20 00:42:54,779 - ERROR - Internal Server Error: /Dashboard/
Traceback (most recent call last):
  File "C:\Users\danie\AppData\Local\Programs\Python\Python310\lib\site-packages\django\db\models\sql\query.py", line 2195, in add_fields
    join_info = self.setup_joins(
  File "C:\Users\danie\AppData\Local\Programs\Python\Python310\lib\site-packages\django\db\models\sql\query.py", line 1863, in setup_joins
    path, final_field, targets, rest = self.names_to_path(
  File "C:\Users\danie\AppData\Local\Programs\Python\Python310\lib\site-packages\django\db\models\sql\query.py", line 1768, in names_to_path
    raise FieldError(
django.core.exceptions.FieldError: Cannot resolve keyword 'fecha_notificacion' into field. Choices are: actu, arancel, arancel_nombre, comuna, demandado, demandante, domicilio, encargo, estadoCausa, estadoNoti, fechaNotificacion, id, mandante, nombTribunal, numjui, repre, soli

During handling of the above exception, another exception occurred:

Traceback (most recent call last):
  File "C:\Users\danie\AppData\Local\Programs\Python\Python310\lib\site-packages\django\core\handlers\exception.py", line 55, in inner
    response = get_response(request)
  File "C:\Users\danie\AppData\Local\Programs\Python\Python310\lib\site-packages\django\core\handlers\base.py", line 197, in _get_response
    response = wrapped_callback(request, *callback_args, **callback_kwargs)
  File "C:\Users\danie\Desktop\proyecto titulo\Causa1\views.py", line 185, in dashboard
    causas = Notificacion.objects.all().values(
  File "C:\Users\danie\AppData\Local\Programs\Python\Python310\lib\site-packages\django\db\models\query.py", line 1360, in values
    clone = self._values(*fields, **expressions)
  File "C:\Users\danie\AppData\Local\Programs\Python\Python310\lib\site-packages\django\db\models\query.py", line 1355, in _values
    clone.query.set_values(fields)
  File "C:\Users\danie\AppData\Local\Programs\Python\Python310\lib\site-packages\django\db\models\sql\query.py", line 2500, in set_values
    self.add_fields(field_names, True)
  File "C:\Users\danie\AppData\Local\Programs\Python\Python310\lib\site-packages\django\db\models\sql\query.py", line 2223, in add_fields
    raise FieldError(
django.core.exceptions.FieldError: Cannot resolve keyword 'fecha_notificacion' into field. Choices are: actu, arancel, arancel_nombre, comuna, demandado, demandante, domicilio, encargo, estadoCausa, estadoNoti, fechaNotificacion, id, mandante, nombTribunal, numjui, repre, soli
2024-11-20 00:46:23,116 - INFO - C:\Users\danie\Desktop\proyecto titulo\Causa1\views.py changed, reloading.
2024-11-20 00:46:29,960 - ERROR - Internal Server Error: /Dashboard/
Traceback (most recent call last):
  File "C:\Users\danie\AppData\Local\Programs\Python\Python310\lib\site-packages\django\core\handlers\exception.py", line 55, in inner
    response = get_response(request)
  File "C:\Users\danie\AppData\Local\Programs\Python\Python310\lib\site-packages\django\core\handlers\base.py", line 197, in _get_response
    response = wrapped_callback(request, *callback_args, **callback_kwargs)
  File "C:\Users\danie\Desktop\proyecto titulo\Causa1\views.py", line 191, in dashboard
    return render(request, 'Causa1/dashboard.html', {
  File "C:\Users\danie\AppData\Local\Programs\Python\Python310\lib\site-packages\django\shortcuts.py", line 25, in render
    content = loader.render_to_string(template_name, context, request, using=using)
  File "C:\Users\danie\AppData\Local\Programs\Python\Python310\lib\site-packages\django\template\loader.py", line 62, in render_to_string
    return template.render(context, request)
  File "C:\Users\danie\AppData\Local\Programs\Python\Python310\lib\site-packages\django\template\backends\django.py", line 107, in render
    return self.template.render(context)
  File "C:\Users\danie\AppData\Local\Programs\Python\Python310\lib\site-packages\django\template\base.py", line 171, in render
    return self._render(context)
  File "C:\Users\danie\AppData\Local\Programs\Python\Python310\lib\site-packages\django\template\base.py", line 163, in _render
    return self.nodelist.render(context)
  File "C:\Users\danie\AppData\Local\Programs\Python\Python310\lib\site-packages\django\template\base.py", line 1008, in render
    return SafeString("".join([node.render_annotated(context) for node in self]))
  File "C:\Users\danie\AppData\Local\Programs\Python\Python310\lib\site-packages\django\template\base.py", line 1008, in <listcomp>
    return SafeString("".join([node.render_annotated(context) for node in self]))
  File "C:\Users\danie\AppData\Local\Programs\Python\Python310\lib\site-packages\django\template\base.py", line 969, in render_annotated
    return self.render(context)
  File "C:\Users\danie\AppData\Local\Programs\Python\Python310\lib\site-packages\django\template\defaulttags.py", line 243, in render
    nodelist.append(node.render_annotated(context))
  File "C:\Users\danie\AppData\Local\Programs\Python\Python310\lib\site-packages\django\template\base.py", line 969, in render_annotated
    return self.render(context)
  File "C:\Users\danie\AppData\Local\Programs\Python\Python310\lib\site-packages\django\template\defaulttags.py", line 480, in render
    url = reverse(view_name, args=args, kwargs=kwargs, current_app=current_app)
  File "C:\Users\danie\AppData\Local\Programs\Python\Python310\lib\site-packages\django\urls\base.py", line 88, in reverse
    return resolver._reverse_with_prefix(view, prefix, *args, **kwargs)
  File "C:\Users\danie\AppData\Local\Programs\Python\Python310\lib\site-packages\django\urls\resolvers.py", line 831, in _reverse_with_prefix
    raise NoReverseMatch(msg)
django.urls.exceptions.NoReverseMatch: Reverse for 'notificar' with arguments '('',)' not found. 1 pattern(s) tried: ['notificar/(?P<causa_id>[0-9]+)/\\Z']
2024-11-20 00:50:33,078 - ERROR - Internal Server Error: /Dashboard/
Traceback (most recent call last):
  File "C:\Users\danie\AppData\Local\Programs\Python\Python310\lib\site-packages\django\core\handlers\exception.py", line 55, in inner
    response = get_response(request)
  File "C:\Users\danie\AppData\Local\Programs\Python\Python310\lib\site-packages\django\core\handlers\base.py", line 197, in _get_response
    response = wrapped_callback(request, *callback_args, **callback_kwargs)
  File "C:\Users\danie\Desktop\proyecto titulo\Causa1\views.py", line 191, in dashboard
    return render(request, 'Causa1/dashboard.html', {
  File "C:\Users\danie\AppData\Local\Programs\Python\Python310\lib\site-packages\django\shortcuts.py", line 25, in render
    content = loader.render_to_string(template_name, context, request, using=using)
  File "C:\Users\danie\AppData\Local\Programs\Python\Python310\lib\site-packages\django\template\loader.py", line 62, in render_to_string
    return template.render(context, request)
  File "C:\Users\danie\AppData\Local\Programs\Python\Python310\lib\site-packages\django\template\backends\django.py", line 107, in render
    return self.template.render(context)
  File "C:\Users\danie\AppData\Local\Programs\Python\Python310\lib\site-packages\django\template\base.py", line 171, in render
    return self._render(context)
  File "C:\Users\danie\AppData\Local\Programs\Python\Python310\lib\site-packages\django\template\base.py", line 163, in _render
    return self.nodelist.render(context)
  File "C:\Users\danie\AppData\Local\Programs\Python\Python310\lib\site-packages\django\template\base.py", line 1008, in render
    return SafeString("".join([node.render_annotated(context) for node in self]))
  File "C:\Users\danie\AppData\Local\Programs\Python\Python310\lib\site-packages\django\template\base.py", line 1008, in <listcomp>
    return SafeString("".join([node.render_annotated(context) for node in self]))
  File "C:\Users\danie\AppData\Local\Programs\Python\Python310\lib\site-packages\django\template\base.py", line 969, in render_annotated
    return self.render(context)
  File "C:\Users\danie\AppData\Local\Programs\Python\Python310\lib\site-packages\django\template\defaulttags.py", line 243, in render
    nodelist.append(node.render_annotated(context))
  File "C:\Users\danie\AppData\Local\Programs\Python\Python310\lib\site-packages\django\template\base.py", line 969, in render_annotated
    return self.render(context)
  File "C:\Users\danie\AppData\Local\Programs\Python\Python310\lib\site-packages\django\template\defaulttags.py", line 480, in render
    url = reverse(view_name, args=args, kwargs=kwargs, current_app=current_app)
  File "C:\Users\danie\AppData\Local\Programs\Python\Python310\lib\site-packages\django\urls\base.py", line 88, in reverse
    return resolver._reverse_with_prefix(view, prefix, *args, **kwargs)
  File "C:\Users\danie\AppData\Local\Programs\Python\Python310\lib\site-packages\django\urls\resolvers.py", line 831, in _reverse_with_prefix
    raise NoReverseMatch(msg)
django.urls.exceptions.NoReverseMatch: Reverse for 'notificar' with arguments '('',)' not found. 1 pattern(s) tried: ['notificar/(?P<causa_id>[0-9]+)/\\Z']
2024-11-20 00:54:22,753 - INFO - C:\Users\danie\Desktop\proyecto titulo\Causa1\views.py changed, reloading.
2024-11-20 01:55:48,781 - INFO - C:\Users\danie\Desktop\proyecto titulo\Causa1\views.py changed, reloading.
