2024-11-25 21:51:06,115 - INFO - C:\Users\danie\Desktop\proyecto titulo\Causa1\views.py changed, reloading.
2024-11-25 21:54:04,791 - INFO - C:\Users\danie\Desktop\proyecto titulo\Causa1\views.py changed, reloading.
2024-11-25 21:54:35,434 - INFO - C:\Users\danie\Desktop\proyecto titulo\Causa1\views.py changed, reloading.
2024-11-25 21:55:03,025 - INFO - C:\Users\danie\Desktop\proyecto titulo\Causa1\views.py changed, reloading.
2024-11-25 22:22:32,996 - INFO - C:\Users\danie\Desktop\proyecto titulo\Causa1\apps.py changed, reloading.
2024-11-25 22:41:29,116 - ERROR - Internal Server Error: /login/
Traceback (most recent call last):
  File "C:\Users\danie\AppData\Local\Programs\Python\Python310\lib\site-packages\django\core\handlers\exception.py", line 55, in inner
    response = get_response(request)
  File "C:\Users\danie\AppData\Local\Programs\Python\Python310\lib\site-packages\django\core\handlers\base.py", line 197, in _get_response
    response = wrapped_callback(request, *callback_args, **callback_kwargs)
  File "C:\Users\danie\Desktop\proyecto titulo\Causa1\views.py", line 120, in login_view
    return render(request, 'Causa1/login.html',{'messages': almacen_mensajes})
UnboundLocalError: local variable 'almacen_mensajes' referenced before assignment
2024-11-25 23:26:01,551 - ERROR - Internal Server Error: /login/
Traceback (most recent call last):
  File "C:\Users\danie\AppData\Local\Programs\Python\Python310\lib\site-packages\django\core\handlers\exception.py", line 55, in inner
    response = get_response(request)
  File "C:\Users\danie\AppData\Local\Programs\Python\Python310\lib\site-packages\django\core\handlers\base.py", line 197, in _get_response
    response = wrapped_callback(request, *callback_args, **callback_kwargs)
  File "C:\Users\danie\Desktop\proyecto titulo\Causa1\views.py", line 120, in login_view
    return render(request, 'Causa1/login.html',{'messages': almacen_mensajes})
UnboundLocalError: local variable 'almacen_mensajes' referenced before assignment
2024-11-25 23:28:05,290 - INFO - C:\Users\danie\Desktop\proyecto titulo\Causa1\views.py changed, reloading.
2024-11-25 23:28:22,748 - ERROR - Internal Server Error: /login/
Traceback (most recent call last):
  File "C:\Users\danie\AppData\Local\Programs\Python\Python310\lib\site-packages\django\core\handlers\exception.py", line 55, in inner
    response = get_response(request)
  File "C:\Users\danie\AppData\Local\Programs\Python\Python310\lib\site-packages\django\core\handlers\base.py", line 197, in _get_response
    response = wrapped_callback(request, *callback_args, **callback_kwargs)
  File "C:\Users\danie\Desktop\proyecto titulo\Causa1\views.py", line 139, in login_view
    return render(request, 'Causa1/login.html',{'messages': almacen_mensajes})
UnboundLocalError: local variable 'almacen_mensajes' referenced before assignment
2024-11-25 23:28:29,531 - ERROR - Internal Server Error: /login/
Traceback (most recent call last):
  File "C:\Users\danie\AppData\Local\Programs\Python\Python310\lib\site-packages\django\core\handlers\exception.py", line 55, in inner
    response = get_response(request)
  File "C:\Users\danie\AppData\Local\Programs\Python\Python310\lib\site-packages\django\core\handlers\base.py", line 197, in _get_response
    response = wrapped_callback(request, *callback_args, **callback_kwargs)
  File "C:\Users\danie\Desktop\proyecto titulo\Causa1\views.py", line 139, in login_view
    return render(request, 'Causa1/login.html',{'messages': almacen_mensajes})
UnboundLocalError: local variable 'almacen_mensajes' referenced before assignment
2024-11-25 23:28:43,823 - INFO - C:\Users\danie\Desktop\proyecto titulo\Causa1\views.py changed, reloading.
2024-11-25 23:28:49,306 - ERROR - Internal Server Error: /login/
Traceback (most recent call last):
  File "C:\Users\danie\AppData\Local\Programs\Python\Python310\lib\site-packages\django\core\handlers\exception.py", line 55, in inner
    response = get_response(request)
  File "C:\Users\danie\AppData\Local\Programs\Python\Python310\lib\site-packages\django\core\handlers\base.py", line 197, in _get_response
    response = wrapped_callback(request, *callback_args, **callback_kwargs)
  File "C:\Users\danie\Desktop\proyecto titulo\Causa1\views.py", line 138, in login_view
    return render(request, 'Causa1/login.html',{'messages': almacen_mensajes})
UnboundLocalError: local variable 'almacen_mensajes' referenced before assignment
2024-11-25 23:30:09,943 - INFO - C:\Users\danie\Desktop\proyecto titulo\Causa1\views.py changed, reloading.
2024-11-25 23:42:52,270 - ERROR - Internal Server Error: /login/
Traceback (most recent call last):
  File "C:\Users\danie\AppData\Local\Programs\Python\Python310\lib\site-packages\django\core\handlers\exception.py", line 55, in inner
    response = get_response(request)
  File "C:\Users\danie\AppData\Local\Programs\Python\Python310\lib\site-packages\django\core\handlers\base.py", line 197, in _get_response
    response = wrapped_callback(request, *callback_args, **callback_kwargs)
  File "C:\Users\danie\Desktop\proyecto titulo\Causa1\views.py", line 121, in login_view
    return render(request, 'Causa1/login.html',{'messages': almacen_mensajes})
  File "C:\Users\danie\AppData\Local\Programs\Python\Python310\lib\site-packages\django\shortcuts.py", line 25, in render
    content = loader.render_to_string(template_name, context, request, using=using)
  File "C:\Users\danie\AppData\Local\Programs\Python\Python310\lib\site-packages\django\template\loader.py", line 62, in render_to_string
    return template.render(context, request)
  File "C:\Users\danie\AppData\Local\Programs\Python\Python310\lib\site-packages\django\template\backends\django.py", line 107, in render
    return self.template.render(context)
  File "C:\Users\danie\AppData\Local\Programs\Python\Python310\lib\site-packages\django\template\base.py", line 171, in render
    return self._render(context)
  File "C:\Users\danie\AppData\Local\Programs\Python\Python310\lib\site-packages\django\template\base.py", line 163, in _render
    return self.nodelist.render(context)
  File "C:\Users\danie\AppData\Local\Programs\Python\Python310\lib\site-packages\django\template\base.py", line 1008, in render
    return SafeString("".join([node.render_annotated(context) for node in self]))
  File "C:\Users\danie\AppData\Local\Programs\Python\Python310\lib\site-packages\django\template\base.py", line 1008, in <listcomp>
    return SafeString("".join([node.render_annotated(context) for node in self]))
  File "C:\Users\danie\AppData\Local\Programs\Python\Python310\lib\site-packages\django\template\base.py", line 969, in render_annotated
    return self.render(context)
  File "C:\Users\danie\AppData\Local\Programs\Python\Python310\lib\site-packages\django\template\defaulttags.py", line 480, in render
    url = reverse(view_name, args=args, kwargs=kwargs, current_app=current_app)
  File "C:\Users\danie\AppData\Local\Programs\Python\Python310\lib\site-packages\django\urls\base.py", line 88, in reverse
    return resolver._reverse_with_prefix(view, prefix, *args, **kwargs)
  File "C:\Users\danie\AppData\Local\Programs\Python\Python310\lib\site-packages\django\urls\resolvers.py", line 831, in _reverse_with_prefix
    raise NoReverseMatch(msg)
django.urls.exceptions.NoReverseMatch: Reverse for 'home' not found. 'home' is not a valid view function or pattern name.
2024-11-25 23:43:36,351 - INFO - C:\Users\danie\Desktop\proyecto titulo\Causa\urls.py changed, reloading.
2024-11-25 23:43:41,206 - ERROR - Internal Server Error: /login/
Traceback (most recent call last):
  File "C:\Users\danie\AppData\Local\Programs\Python\Python310\lib\site-packages\django\core\handlers\exception.py", line 55, in inner
    response = get_response(request)
  File "C:\Users\danie\AppData\Local\Programs\Python\Python310\lib\site-packages\django\core\handlers\base.py", line 197, in _get_response
    response = wrapped_callback(request, *callback_args, **callback_kwargs)
  File "C:\Users\danie\Desktop\proyecto titulo\Causa1\views.py", line 121, in login_view
    return render(request, 'Causa1/login.html',{'messages': almacen_mensajes})
  File "C:\Users\danie\AppData\Local\Programs\Python\Python310\lib\site-packages\django\shortcuts.py", line 25, in render
    content = loader.render_to_string(template_name, context, request, using=using)
  File "C:\Users\danie\AppData\Local\Programs\Python\Python310\lib\site-packages\django\template\loader.py", line 62, in render_to_string
    return template.render(context, request)
  File "C:\Users\danie\AppData\Local\Programs\Python\Python310\lib\site-packages\django\template\backends\django.py", line 107, in render
    return self.template.render(context)
  File "C:\Users\danie\AppData\Local\Programs\Python\Python310\lib\site-packages\django\template\base.py", line 171, in render
    return self._render(context)
  File "C:\Users\danie\AppData\Local\Programs\Python\Python310\lib\site-packages\django\template\base.py", line 163, in _render
    return self.nodelist.render(context)
  File "C:\Users\danie\AppData\Local\Programs\Python\Python310\lib\site-packages\django\template\base.py", line 1008, in render
    return SafeString("".join([node.render_annotated(context) for node in self]))
  File "C:\Users\danie\AppData\Local\Programs\Python\Python310\lib\site-packages\django\template\base.py", line 1008, in <listcomp>
    return SafeString("".join([node.render_annotated(context) for node in self]))
  File "C:\Users\danie\AppData\Local\Programs\Python\Python310\lib\site-packages\django\template\base.py", line 969, in render_annotated
    return self.render(context)
  File "C:\Users\danie\AppData\Local\Programs\Python\Python310\lib\site-packages\django\template\defaulttags.py", line 480, in render
    url = reverse(view_name, args=args, kwargs=kwargs, current_app=current_app)
  File "C:\Users\danie\AppData\Local\Programs\Python\Python310\lib\site-packages\django\urls\base.py", line 88, in reverse
    return resolver._reverse_with_prefix(view, prefix, *args, **kwargs)
  File "C:\Users\danie\AppData\Local\Programs\Python\Python310\lib\site-packages\django\urls\resolvers.py", line 831, in _reverse_with_prefix
    raise NoReverseMatch(msg)
django.urls.exceptions.NoReverseMatch: Reverse for 'home' not found. 'home' is not a valid view function or pattern name.
2024-11-25 23:43:44,817 - ERROR - Internal Server Error: /login/
Traceback (most recent call last):
  File "C:\Users\danie\AppData\Local\Programs\Python\Python310\lib\site-packages\django\core\handlers\exception.py", line 55, in inner
    response = get_response(request)
  File "C:\Users\danie\AppData\Local\Programs\Python\Python310\lib\site-packages\django\core\handlers\base.py", line 197, in _get_response
    response = wrapped_callback(request, *callback_args, **callback_kwargs)
  File "C:\Users\danie\Desktop\proyecto titulo\Causa1\views.py", line 121, in login_view
    return render(request, 'Causa1/login.html',{'messages': almacen_mensajes})
  File "C:\Users\danie\AppData\Local\Programs\Python\Python310\lib\site-packages\django\shortcuts.py", line 25, in render
    content = loader.render_to_string(template_name, context, request, using=using)
  File "C:\Users\danie\AppData\Local\Programs\Python\Python310\lib\site-packages\django\template\loader.py", line 62, in render_to_string
    return template.render(context, request)
  File "C:\Users\danie\AppData\Local\Programs\Python\Python310\lib\site-packages\django\template\backends\django.py", line 107, in render
    return self.template.render(context)
  File "C:\Users\danie\AppData\Local\Programs\Python\Python310\lib\site-packages\django\template\base.py", line 171, in render
    return self._render(context)
  File "C:\Users\danie\AppData\Local\Programs\Python\Python310\lib\site-packages\django\template\base.py", line 163, in _render
    return self.nodelist.render(context)
  File "C:\Users\danie\AppData\Local\Programs\Python\Python310\lib\site-packages\django\template\base.py", line 1008, in render
    return SafeString("".join([node.render_annotated(context) for node in self]))
  File "C:\Users\danie\AppData\Local\Programs\Python\Python310\lib\site-packages\django\template\base.py", line 1008, in <listcomp>
    return SafeString("".join([node.render_annotated(context) for node in self]))
  File "C:\Users\danie\AppData\Local\Programs\Python\Python310\lib\site-packages\django\template\base.py", line 969, in render_annotated
    return self.render(context)
  File "C:\Users\danie\AppData\Local\Programs\Python\Python310\lib\site-packages\django\template\defaulttags.py", line 480, in render
    url = reverse(view_name, args=args, kwargs=kwargs, current_app=current_app)
  File "C:\Users\danie\AppData\Local\Programs\Python\Python310\lib\site-packages\django\urls\base.py", line 88, in reverse
    return resolver._reverse_with_prefix(view, prefix, *args, **kwargs)
  File "C:\Users\danie\AppData\Local\Programs\Python\Python310\lib\site-packages\django\urls\resolvers.py", line 831, in _reverse_with_prefix
    raise NoReverseMatch(msg)
django.urls.exceptions.NoReverseMatch: Reverse for 'home' not found. 'home' is not a valid view function or pattern name.
2024-11-25 23:43:48,984 - INFO - C:\Users\danie\Desktop\proyecto titulo\Causa\urls.py changed, reloading.
2024-11-26 16:13:16,666 - WARNING - Not Found: /favicon.ico
2024-11-26 16:28:40,667 - WARNING - Not Found: /favicon.ico
